Workbook

Sheet TIPS
A1: TIPS:
A3: 1. This matrix is a micro clash detection matrix intended to reduce the number of false positives and increase confidence in clash results, leading to pathways to automate the process of digital coordination.
A5: 2. This matrix is to be used by Services teams and Project Managers to instruct the BIM team to prioritise and execute clash detection tasks.
A8: 3. Matrix snapshot and explanation:
J12: Selection B list of Items Categories
J15: Clash Task Priority - refer to Clash Matrix Legend
A18: Selection A list of Items Categories
J21: Clearance factors - refer to Clash Matrix Legend
A25: 4. Workflow:
A26: Start with the Clash Matrix and refer back to the Clash Matrix Legend
A27: Use the Clash Task (Output) to filter by task priority and copy the associated task into the coordination software (such as Revizto)
A28: [Imporntant] | B28: After updating the clash matrix, please click 'Refresh All'are refreshed under the 'Clash Task Output' section

Sheet Clash Matrix (Update to suit)
A1: Selection A (A) | B1: Selection (B) | C1: =A2 -> ARC_Columns* | D1: =A4 -> ARC_Ceiling | E1: =A6 -> ARC_Doors* | F1: =A8 -> ARC_Gen Model & Casework* | G1: =A10 -> ARC_Roof | H1: =A12 -> ARC_Fire & Acoustic Wall | I1: =A14 -> ARC_Windows | J1: =A16 -> ARC_Services Walkway | K1: =A18 -> ARC_Accessible Path | L1: =A20 -> SRV_Access Panel | M1: =A22 -> ARC_Lighting Fixtures | N1: =A24 -> ARC_Plumbing Fixtures | O1: ='Item Categories'!C14 -> ARC_SOG Floor Insulation | P1: =A28 -> STR_Seismic Elements | Q1: =A30 -> STR_Conc work Excl Floor Slab | R1: =A32 -> STR_Steelwork (Bracing and Columns) | S1: =A34 -> STR Floor | T1: =A36 -> HYD_Uninsulated Pipes and Acc | U1: =A38 -> HYD_Pipe Insulation | V1: =A40 -> HYD_Uninsulated Hot and Cold Pipes and Acc | W1: =A42 -> HYD_Hot and Cold Insulation | X1: ='Item Categories'!D23 -> HYD_Plumbing Fixture | Y1: ='Item Categories'!C24 -> MEC_Air Terminals | Z1: ='Item Categories'!C25 -> MEC_Uninsulated Duct and Acc | AA1: ='Item Categories'!C26 -> MEC_Duct Insulation | AB1: ='Item Categories'!C27 -> MEC_Pipe Insulation | AC1: ='Item Categories'!C28 -> MEC_Uninsulated Pipes and Acc | AD1: ='Item Categories'!C29 -> MEC_Uninulated Flexi duct | AE1: ='Item Categories'!C30 -> MEC_Equipment | AF1: ='Item Categories'!C31 -> ELE_Cable Tray and Fittings | AG1: ='Item Categories'!C32 -> ELE_Conduit* | AH1: ='Item Categories'!C33 -> ELE_Electrical Equip. | AI1: ='Item Categories'!C34 -> ELE_Small Devices | AJ1: ='Item Categories'!C35 -> ELE_Services Lighting Fixtures | AK1: ='Item Categories'!C36 -> FIR_Fire Pipes | AL1: ='Item Categories'!C37 -> FIR_Sprinklers Heads | AM1: ='Item Categories'!C38 -> FIR_Heat or Smoke Detectors
A2: ='Item Categories'!C2 -> ARC_Columns*
A4: ='Item Categories'!C3 -> ARC_Ceiling | E4: T2 | H4: T2 | T4: T2 | U4: T2 | V4: T2 | W4: T2 | X4: T2 | Z4: T2 | AA4: T2 | AB4: T2 | AC4: T2 | AD4: T2 | AE4: T2 | AF4: T2 | AG4: T2 | AH4: T2 | AI4: T2 | AK4: T2
E5: HC | H5: HC | T5: C100V | U5: C100V | V5: C100V | W5: C100V | X5: C100V | Z5: C100V | AA5: C100V | AB5: C100V | AC5: C100V | AD5: C100V | AE5: C100V | AF5: C100V | AG5: C100V | AH5: C100V | AI5: C100V | AK5: C100V
A6: ='Item Categories'!C4 -> ARC_Doors* | J6: T3 | Q6: T2 | R6: T2 | S6: T2 | Y6: T2 | AE6: T2 | AH6: T3
J7: HC | Q7: HC | R7: HC | S7: HC | Y7: C50 | AE7: C50 | AH7: HC
A8: ='Item Categories'!C5 -> ARC_Gen Model & Casework* | H8: T4 | I8: T4 | J8: T4 | L8: T4 | N8: T4 | P8: T4 | Q8: T4 | R8: T4 | S8: T4 | T8: T4 | U8: T4 | V8: T4 | W8: T4 | X8: T4 | Y8: T4 | Z8: T4 | AA8: T4 | AB8: T4 | AC8: T4 | AD8: T4 | AE8: T4 | AF8: T4 | AG8: T4 | AH8: T4 | AI8: T4 | AJ8: T4 | AK8: T4
H9: HC | I9: HC | J9: HC | L9: HC | N9: HC | P9: HC | Q9: HC | R9: HC | S9: HC | T9: HC | U9: HC | V9: HC | W9: HC | X9: HC | Y9: HC | Z9: HC | AA9: HC | AB9: HC | AC9: HC | AD9: HC | AE9: HC | AF9: HC | AG9: HC | AH9: HC | AI9: HC | AJ9: HC | AK9: HC
A10: ='Item Categories'!C6 -> ARC_Roof
A12: ='Item Categories'!C7 -> ARC_Fire & Acoustic Wall | L12: T2 | P12: T2 | Q12: T2 | R12: T2 | S12: T2 | T12: T2 | U12: T2 | V12: T2 | W12: T2 | X12: T2 | Z12: T2 | AA12: T2 | AB12: T2 | AC12: T2 | AD12: T2 | AE12: T2 | AF12: T2 | AG12: T2 | AH12: T2 | AJ12: T2 | AK12: T2
L13: C50 | P13: HC | Q13: HC | R13: HC | S13: HC | T13: C50 | U13: C50 | V13: C50 | W13: C50 | X13: C50 | Z13: C50 | AA13: C50 | AB13: C50 | AC13: C50 | AD13: C50 | AE13: C50 | AF13: C50 | AG13: C50 | AH13: C50 | AJ13: C50 | AK13: C50
A14: ='Item Categories'!C8 -> ARC_Windows | Q14: T2 | R14: T2 | S14: T2
Q15: HC | R15: HC | S15: HC
A16: ='Item Categories'!C9 -> ARC_Services Walkway | L16: T3 | N16: T3 | O16: T3 | P16: T3 | Q16: T3 | R16: T3 | S16: T3 | T16: T3 | U16: T3 | V16: T3 | W16: T3 | X16: T3 | Y16: T3 | Z16: T3 | AA16: T3 | AB16: T3 | AC16: T3 | AD16: T3 | AE16: T3 | AF16: T3 | AG16: T3 | AH16: T3 | AI16: T3 | AJ16: T3 | AK16: T3 | AL16: T3 | AM16: T3
L17: HC | N17: HC | O17: HC | P17: HC | Q17: HC | R17: HC | S17: HC | T17: HC | U17: HC | V17: HC | W17: HC | X17: HC | Y17: HC | Z17: HC | AA17: HC | AB17: HC | AC17: HC | AD17: HC | AE17: HC | AF17: HC | AG17: HC | AH17: HC | AI17: HC | AJ17: HC | AK17: HC | AL17: HC | AM17: HC
A18: ='Item Categories'!C10 -> ARC_Accessible Path
A20: ='Item Categories'!C11 -> SRV_Access Panel | N20: T3 | P20: T3 | R20: T3 | T20: T3 | U20: T3 | V20: T3 | W20: T3 | Y20: T3 | Z20: T3 | AA20: T3 | AB20: T3 | AC20: T3 | AD20: T3 | AE20: T3 | AF20: T3 | AG20: T3 | AH20: T3 | AI20: T3 | AJ20: T3 | AK20: T3
N21: C600V | P21: C600V | R21: C600V | T21: C600V | U21: C600V | V21: C600V | W21: C600V | Y21: C600V | Z21: C600V | AA21: C600V | AB21: C600V | AC21: C600V | AD21: C600V | AE21: C600V | AF21: C600V | AG21: C600V | AH21: C600V | AI21: C600V | AJ21: C600V | AK21: C600V
A22: ='Item Categories'!C12 -> ARC_Lighting Fixtures | AJ22: T3
AJ23: HC
A24: ='Item Categories'!C13 -> ARC_Plumbing Fixtures | P24: T3 | Q24: T3 | R24: T3 | T24: T3 | U24: T3 | V24: T3 | W24: T3 | X24: T3 | Y24: T3 | Z24: T3 | AA24: T3 | AB24: T3 | AC24: T3 | AD24: T3 | AE24: T3 | AF24: T3 | AG24: T3 | AH24: T3 | AI24: T3 | AJ24: T3
P25: C50 | Q25: C50 | R25: C50 | T25: C50 | U25: C50 | V25: C50 | W25: C50 | X25: C50 | Y25: C50 | Z25: C50 | AA25: C50 | AB25: C50 | AC25: C50 | AD25: C50 | AE25: C50 | AF25: C50 | AG25: C50 | AH25: C50 | AI25: C50 | AJ25: C50
A26: ='Item Categories'!C14 -> ARC_SOG Floor Insulation | T26: T1 | U26: T1 | V26: T1 | W26: T1 | X26: T1 | Y26: T1 | Z26: T1 | AA26: T1 | AB26: T1 | AC26: T1 | AD26: T1 | AE26: T1 | AF26: T1 | AG26: T1 | AH26: T1 | AK26: T1
T27: HC | U27: HC | V27: HC | W27: HC | X27: HC | Y27: HC | Z27: HC | AA27: HC | AB27: HC | AC27: HC | AD27: HC | AE27: HC | AF27: HC | AG27: HC | AH27: HC | AK27: HC
A28: ='Item Categories'!C15 -> STR_Seismic Elements | Q28: T2 | R28: T2 | S28: T2 | T28: T2 | U28: T2 | V28: T2 | W28: T2 | X28: T2 | Y28: T2 | Z28: T2 | AA28: T2 | AB28: T2 | AC28: T2 | AD28: T2 | AE28: T2 | AF28: T2 | AG28: T2 | AH28: T2 | AI28: T2 | AJ28: T2 | AK28: T2
Q29: C50 | R29: C50 | S29: C50 | T29: C50 | U29: C50 | V29: C50 | W29: C50 | X29: C50 | Y29: C50 | Z29: C50 | AA29: C50 | AB29: C50 | AC29: C50 | AD29: C50 | AE29: C50 | AF29: C50 | AG29: C50 | AH29: C50 | AI29: C50 | AJ29: C50 | AK29: C50
A30: ='Item Categories'!C16 -> STR_Conc work Excl Floor Slab | T30: T1 | U30: T1 | V30: T1 | W30: T1 | X30: T1 | Y30: T1 | Z30: T1 | AA30: T1 | AB30: T1 | AC30: T1 | AD30: T1 | AE30: T1 | AF30: T1 | AG30: T1 | AH30: T1 | AI30: T1 | AJ30: T1 | AK30: T1
T31: C50 | U31: C50 | V31: C50 | W31: C50 | X31: C50 | Y31: C50 | Z31: C50 | AA31: C50 | AB31: C50 | AC31: C50 | AD31: C50 | AE31: C50 | AF31: C50 | AG31: C50 | AH31: C50 | AI31: C50 | AJ31: C50 | AK31: C50
A32: ='Item Categories'!C17 -> STR_Steelwork (Bracing and Columns) | T32: T1 | U32: T1 | V32: T1 | W32: T1 | Y32: T1 | Z32: T1 | AA32: T1 | AB32: T1 | AC32: T1 | AD32: T1 | AE32: T1 | AF32: T1 | AG32: T1 | AH32: T1 | AI32: T1 | AJ32: T1
T33: C50 | U33: C50 | V33: C50 | W33: C50 | Y33: C50 | Z33: C50 | AA33: C50 | AB33: C50 | AC33: C50 | AD33: C50 | AE33: C50 | AF33: C50 | AG33: C50 | AH33: C50 | AI33: C50 | AJ33: C50
A34: ='Item Categories'!C18 -> STR Floor | T34: T1 | U34: T1 | V34: T1 | W34: T1 | Y34: T1 | Z34: T1 | AA34: T1 | AB34: T1 | AC34: T1 | AD34: T1 | AE34: T1 | AF34: T1 | AG34: T1 | AH34: T1 | AI34: T1 | AJ34: T1 | AK34: T1
T35: C50 | U35: C50 | V35: C50 | W35: C50 | Y35: C50 | Z35: C50 | AA35: C50 | AB35: C50 | AC35: C50 | AD35: C50 | AE35: C50 | AF35: C50 | AG35: C50 | AH35: C50 | AI35: C50 | AJ35: C50 | AK35: C50
A36: ='Item Categories'!C19 -> HYD_Uninsulated Pipes and Acc | U36: T2 | V36: T2 | W36: T2 | X36: T2 | Y36: T2 | Z36: T2 | AA36: T2 | AB36: T2 | AC36: T2 | AD36: T2 | AE36: T2 | AF36: T2 | AG36: T2 | AH36: T2 | AI36: T2 | AJ36: T2 | AK36: T2 | AL36: T2 | AM36: T2
U37: C50 | V37: C50 | W37: C50 | X37: C50 | Y37: C50 | Z37: C50 | AA37: C50 | AB37: C50 | AC37: C50 | AD37: C50 | AE37: C50 | AF37: C50 | AG37: C50 | AH37: C50 | AI37: C50 | AJ37: C50 | AK37: C50 | AL37: C50 | AM37: C50
A38: ='Item Categories'!C20 -> HYD_Pipe Insulation | V38: T2 | W38: T2 | X38: T2 | Y38: T2 | Z38: T2 | AA38: T2 | AB38: T2 | AC38: T2 | AD38: T2 | AE38: T2 | AF38: T2 | AG38: T2 | AH38: T2 | AI38: T2 | AJ38: T2 | AK38: T2 | AL38: T2 | AM38: T2
V39: C50 | W39: C50 | X39: C50 | Y39: C50 | Z39: C50 | AA39: C50 | AB39: C50 | AC39: C50 | AD39: C50 | AE39: C50 | AF39: C50 | AG39: C50 | AH39: C50 | AI39: C50 | AJ39: C50 | AK39: C50 | AL39: C50 | AM39: C50
A40: ='Item Categories'!C21 -> HYD_Uninsulated Hot and Cold Pipes and Acc | W40: T2 | X40: T2 | Y40: T2 | Z40: T2 | AA40: T2 | AB40: T2 | AC40: T2 | AD40: T2 | AE40: T2 | AF40: T2 | AG40: T2 | AH40: T2 | AI40: T2 | AJ40: T2 | AK40: T2 | AL40: T2 | AM40: T2
W41: C50 | X41: C50 | Y41: C50 | Z41: C50 | AA41: C50 | AB41: C50 | AC41: C50 | AD41: C50 | AE41: C50 | AF41: C50 | AG41: C50 | AH41: C50 | AI41: C50 | AJ41: C50 | AK41: C50 | AL41: C50 | AM41: C50
A42: ='Item Categories'!C22 -> HYD_Hot and Cold Insulation | X42: T2 | Y42: T2 | Z42: T2 | AA42: T2 | AB42: T2 | AC42: T2 | AD42: T2 | AE42: T2 | AF42: T2 | AG42: T2 | AH42: T2 | AI42: T2 | AJ42: T2 | AK42: T2 | AL42: T2 | AM42: T2
X43: C50 | Y43: C50 | Z43: C50 | AA43: C50 | AB43: C50 | AC43: C50 | AD43: C50 | AE43: C50 | AF43: C50 | AG43: C50 | AH43: C50 | AI43: C50 | AJ43: C50 | AK43: C50 | AL43: C50 | AM43: C50
...

Sheet Rawdata (Do not edit)
A1: Clash Task Category | B1: Clearance | C1: Selection A | D1: Selection B | E1: Clash Task Name
A2: {=TRANSPOSE('Clash Matrix (Update to suit)'!C2:AM2)} -> 0 | B2: {=TRANSPOSE('Clash Matrix (Update to suit)'!C3:AM3)} -> 0 | C2: ='Clash Matrix (Update to suit)'!$A$2 -> ARC_Columns* | D2: {=TRANSPOSE('Clash Matrix (Update to suit)'!C1:AM1)} -> ARC_Columns* | E2: ="NL-"&B2& "-"& C2&" vs "&D2 -> NL-0-ARC_Columns* vs ARC_Columns*
A3: 0 | B3: 0 | C3: ='Clash Matrix (Update to suit)'!$A$2 -> ARC_Columns* | D3: ARC_Ceiling | E3: ="NL-"&B3& "-"& C3&" vs "&D3 -> NL-0-ARC_Columns* vs ARC_Ceiling
A4: 0 | B4: 0 | C4: ='Clash Matrix (Update to suit)'!$A$2 -> ARC_Columns* | D4: ARC_Doors* | E4: ="NL-"&B4& "-"& C4&" vs "&D4 -> NL-0-ARC_Columns* vs ARC_Doors*
A5: 0 | B5: 0 | C5: ='Clash Matrix (Update to suit)'!$A$2 -> ARC_Columns* | D5: ARC_Gen Model & Casework* | E5: ="NL-"&B5& "-"& C5&" vs "&D5 -> NL-0-ARC_Columns* vs ARC_Gen Model & Casework*
A6: 0 | B6: 0 | C6: ='Clash Matrix (Update to suit)'!$A$2 -> ARC_Columns* | D6: ARC_Roof | E6: ="NL-"&B6& "-"& C6&" vs "&D6 -> NL-0-ARC_Columns* vs ARC_Roof
A7: 0 | B7: 0 | C7: ='Clash Matrix (Update to suit)'!$A$2 -> ARC_Columns* | D7: ARC_Fire & Acoustic Wall | E7: ="NL-"&B7& "-"& C7&" vs "&D7 -> NL-0-ARC_Columns* vs ARC_Fire & Acoustic Wall
A8: 0 | B8: 0 | C8: ='Clash Matrix (Update to suit)'!$A$2 -> ARC_Columns* | D8: ARC_Windows | E8: ="NL-"&B8& "-"& C8&" vs "&D8 -> NL-0-ARC_Columns* vs ARC_Windows
A9: 0 | B9: 0 | C9: ='Clash Matrix (Update to suit)'!$A$2 -> ARC_Columns* | D9: ARC_Services Walkway | E9: ="NL-"&B9& "-"& C9&" vs "&D9 -> NL-0-ARC_Columns* vs ARC_Services Walkway
A10: 0 | B10: 0 | C10: ='Clash Matrix (Update to suit)'!$A$2 -> ARC_Columns* | D10: ARC_Accessible Path | E10: ="NL-"&B10& "-"& C10&" vs "&D10 -> NL-0-ARC_Columns* vs ARC_Accessible Path
A11: 0 | B11: 0 | C11: ='Clash Matrix (Update to suit)'!$A$2 -> ARC_Columns* | D11: SRV_Access Panel | E11: ="NL-"&B11& "-"& C11&" vs "&D11 -> NL-0-ARC_Columns* vs SRV_Access Panel
A12: 0 | B12: 0 | C12: ='Clash Matrix (Update to suit)'!$A$2 -> ARC_Columns* | D12: ARC_Lighting Fixtures | E12: ="NL-"&B12& "-"& C12&" vs "&D12 -> NL-0-ARC_Columns* vs ARC_Lighting Fixtures
A13: 0 | B13: 0 | C13: ='Clash Matrix (Update to suit)'!$A$2 -> ARC_Columns* | D13: ARC_Plumbing Fixtures | E13: ="NL-"&B13& "-"& C13&" vs "&D13 -> NL-0-ARC_Columns* vs ARC_Plumbing Fixtures
A14: 0 | B14: 0 | C14: ='Clash Matrix (Update to suit)'!$A$2 -> ARC_Columns* | D14: ARC_SOG Floor Insulation | E14: ="NL-"&B14& "-"& C14&" vs "&D14 -> NL-0-ARC_Columns* vs ARC_SOG Floor Insulation
... A38: 0 | B38: 0 | C38: ='Clash Matrix (Update to suit)'!$A$2 -> ARC_Columns* | D38: FIR_Heat or Smoke Detectors | E38: ="NL-"&B38& "-"& C38&" vs "&D38 -> NL-0-ARC_Columns* vs FIR_Heat or Smoke Detectors
A39: {=TRANSPOSE('Clash Matrix (Update to suit)'!D4:AM4)} -> 0 | B39: {=TRANSPOSE('Clash Matrix (Update to suit)'!D5:AM5)} -> 0 | C39: ='Item Categories'!C3 -> ARC_Ceiling | D39: {=TRANSPOSE('Clash Matrix (Update to suit)'!D1:AM1)} -> ARC_Ceiling | E39: ="NL-"&B39& "-"& C39&" vs "&D39 -> NL-0-ARC_Ceiling vs ARC_Ceiling
A40: T2 | B40: HC | C40: ARC_Ceiling | D40: ARC_Doors* | E40: ="NL-"&B40& "-"& C40&" vs "&D40 -> NL-HC-ARC_Ceiling vs ARC_Doors*
A41: 0 | B41: 0 | C41: ARC_Ceiling | D41: ARC_Gen Model & Casework* | E41: ="NL-"&B41& "-"& C41&" vs "&D41 -> NL-0-ARC_Ceiling vs ARC_Gen Model & Casework*
A42: 0 | B42: 0 | C42: ARC_Ceiling | D42: ARC_Roof | E42: ="NL-"&B42& "-"& C42&" vs "&D42 -> NL-0-ARC_Ceiling vs ARC_Roof
A43: T2 | B43: HC | C43: ARC_Ceiling | D43: ARC_Fire & Acoustic Wall | E43: ="NL-"&B43& "-"& C43&" vs "&D43 -> NL-HC-ARC_Ceiling vs ARC_Fire & Acoustic Wall
A44: 0 | B44: 0 | C44: ARC_Ceiling | D44: ARC_Windows | E44: ="NL-"&B44& "-"& C44&" vs "&D44 -> NL-0-ARC_Ceiling vs ARC_Windows
A45: 0 | B45: 0 | C45: ARC_Ceiling | D45: ARC_Services Walkway | E45: ="NL-"&B45& "-"& C45&" vs "&D45 -> NL-0-ARC_Ceiling vs ARC_Services Walkway
A46: 0 | B46: 0 | C46: ARC_Ceiling | D46: ARC_Accessible Path | E46: ="NL-"&B46& "-"& C46&" vs "&D46 -> NL-0-ARC_Ceiling vs ARC_Accessible Path
A47: 0 | B47: 0 | C47: ARC_Ceiling | D47: SRV_Access Panel | E47: ="NL-"&B47& "-"& C47&" vs "&D47 -> NL-0-ARC_Ceiling vs SRV_Access Panel
A48: 0 | B48: 0 | C48: ARC_Ceiling | D48: ARC_Lighting Fixtures | E48: ="NL-"&B48& "-"& C48&" vs "&D48 -> NL-0-ARC_Ceiling vs ARC_Lighting Fixtures
A49: 0 | B49: 0 | C49: ARC_Ceiling | D49: ARC_Plumbing Fixtures | E49: ="NL-"&B49& "-"& C49&" vs "&D49 -> NL-0-ARC_Ceiling vs ARC_Plumbing Fixtures
A50: 0 | B50: 0 | C50: ARC_Ceiling | D50: ARC_SOG Floor Insulation | E50: ="NL-"&B50& "-"& C50&" vs "&D50 -> NL-0-ARC_Ceiling vs ARC_SOG Floor Insulation
A51: 0 | B51: 0 | C51: ARC_Ceiling | D51: STR_Seismic Elements | E51: ="NL-"&B51& "-"& C51&" vs "&D51 -> NL-0-ARC_Ceiling vs STR_Seismic Elements
A52: 0 | B52: 0 | C52: ARC_Ceiling | D52: STR_Conc work Excl Floor Slab | E52: ="NL-"&B52& "-"& C52&" vs "&D52 -> NL-0-ARC_Ceiling vs STR_Conc work Excl Floor Slab
A53: 0 | B53: 0 | C53: ARC_Ceiling | D53: STR_Steelwork (Bracing and Columns) | E53: ="NL-"&B53& "-"& C53&" vs "&D53 -> NL-0-ARC_Ceiling vs STR_Steelwork (Bracing and Columns)
A54: 0 | B54: 0 | C54: ARC_Ceiling | D54: STR Floor | E54: ="NL-"&B54& "-"& C54&" vs "&D54 -> NL-0-ARC_Ceiling vs STR Floor
A55: T2 | B55: C100V | C55: ARC_Ceiling | D55: HYD_Uninsulated Pipes and Acc | E55: ="NL-"&B55& "-"& C55&" vs "&D55 -> NL-C100V-ARC_Ceiling vs HYD_Uninsulated Pipes and Acc
A56: T2 | B56: C100V | C56: ARC_Ceiling | D56: HYD_Pipe Insulation | E56: ="NL-"&B56& "-"& C56&" vs "&D56 -> NL-C100V-ARC_Ceiling vs HYD_Pipe Insulation
A57: T2 | B57: C100V | C57: ARC_Ceiling | D57: HYD_Uninsulated Hot and Cold Pipes and Acc | E57: ="NL-"&B57& "-"& C57&" vs "&D57 -> NL-C100V-ARC_Ceiling vs HYD_Uninsulated Hot and Cold Pipes and Acc
A58: T2 | B58: C100V | C58: ARC_Ceiling | D58: HYD_Hot and Cold Insulation | E58: ="NL-"&B58& "-"& C58&" vs "&D58 -> NL-C100V-ARC_Ceiling vs HYD_Hot and Cold Insulation
A59: T2 | B59: C100V | C59: ARC_Ceiling | D59: HYD_Plumbing Fixture | E59: ="NL-"&B59& "-"& C59&" vs "&D59 -> NL-C100V-ARC_Ceiling vs HYD_Plumbing Fixture
A60: 0 | B60: 0 | C60: ARC_Ceiling | D60: MEC_Air Terminals | E60: ="NL-"&B60& "-"& C60&" vs "&D60 -> NL-0-ARC_Ceiling vs MEC_Air Terminals
A61: T2 | B61: C100V | C61: ARC_Ceiling | D61: MEC_Uninsulated Duct and Acc | E61: ="NL-"&B61& "-"& C61&" vs "&D61 -> NL-C100V-ARC_Ceiling vs MEC_Uninsulated Duct and Acc
A62: T2 | B62: C100V | C62: ARC_Ceiling | D62: MEC_Duct Insulation | E62: ="NL-"&B62& "-"& C62&" vs "&D62 -> NL-C100V-ARC_Ceiling vs MEC_Duct Insulation
A63: T2 | B63: C100V | C63: ARC_Ceiling | D63: MEC_Pipe Insulation | E63: ="NL-"&B63& "-"& C63&" vs "&D63 -> NL-C100V-ARC_Ceiling vs MEC_Pipe Insulation
...

Sheet Clash Matrix Legend
A1: NL Clash Matrix Legend
A2: Clash Status | B2: Description | C2: Comment
A3: Blocker | B3: The clash to be raised and assigned to either the lead consultant or BIM partners.
A4: CR (Critical)
A5: MA (Major) | B5: Clash classified as Major, but can be resolved during construction. | C5: Pipework > 50mm is graded as a Major Priority, < 50mm is graded as a Minor Priority in Revizto Clash Automation.
A6: Mi (Minor) | B6: Clash classified as Minor, but can be resolved during construction. | C6: Pipework > 50mm is graded as a Major Priority, < 50mm is graded as a Minor Priority in Revizto Clash Automation.
A7: Trivial | B7: False positive. Not a real clash, can be ignore during clashing (Flex pipes...)
A8: Clearance Matrix Legend
A9: C50 | B9: Clearance set 50mm | C9: Vertical and Horizontal Clearance
A10: C100V | B10: Clearance set 100mm vertical only, Horizontal 50mm as default
A11: C150V | B11: Clearance set (150mm) vertical only Horizontal 50mm as default
A12: HC | B12: Hard Clash, 0mm Tolerance
A13: CXXXV | B13: Clearance set (project Specific) vertical only Horizontal 50mm as default
A14: Clash Task Priority
A15: T1 | B15: Clash Task Scope #1 BIM team to be briefed what's the first major clash tasks to be done as per project timeline. | C15: For example: Concrete work Underground Drainage Work Civil Steel work
A16: T2 | B16: Clash Task Scope #2 as per project timeline. | C16: For example: Services walkway Access panel Fire rated timber framed wall Fire Damper Ceiling Pipework Above Ground Duct work Above Ground
A17: T3 | B17: Clash Task Scope #3 as per project timeline. | C17: For example: Seismic Secondary framing Accessible pathway
A18: T4 | B18: Clash Task Scope #4 as per project timeline. | C18: For example: Fitout
A19: T5 | B19: Additional Task outside template | C19: Required manual added onto Revizto Clash Automation

Sheet Item Categories
A1: No. | B1: Discipline | C1: Element Name | D1: Full Description | E1: Comment
A2: 01 | B2: Architecture | C2: ARC_Columns* | D2: Architectural Columns* | E2: Architectural might include column element, worth checking the column locations vs Structural columns'
A3: 01 | B3: Architecture | C3: ARC_Ceiling | D3: Ceiling
A4: 01 | B4: Architecture | C4: ARC_Doors* | D4: Doors* | E4: Need to considering modelling clearence zone aronud door. If not, the services walkway clerance zone to be modelling
A5: 01 | B5: Architecture | C5: ARC_Gen Model & Casework* | D5: Generic Model & Casework* | E5: Contain Seismic modelling. Further note. BEP to be clearly define the modelling practice. All Casework and generic modelling to be defined clearlly with workset. Including Lift door openings, channel drain
A6: 01 | B6: Architecture | C6: ARC_Roof | D6: Roof
A7: 01 | B7: Architecture | C7: ARC_Fire & Acoustic Wall | D7: Steel & Timber Framed Walls (Fire & Acoustic Wall)
A8: 01 | B8: Architecture | C8: ARC_Windows | D8: Windows
A9: 01 | B9: Architecture | C9: ARC_Services Walkway | D9: Special Items Services walk ways | E9: Services walkway to be model if the consultant models have not included
A10: 01 | B10: Architecture | C10: ARC_Accessible Path | D10: Special Items Accessible Walk Path | E10: ie, Fire Escaping Path
A11: 04 | B11: Services | C11: SRV_Access Panel | D11: Access Panel | E11: fitting access point ie, ceiling access panel
A12: 01 | B12: Architecture | C12: ARC_Lighting Fixtures | D12: Lighting Fixtures
A13: 01 | B13: Architecture | C13: ARC_Plumbing Fixtures | D13: Plumbing Fixtures | E13: Final procurement schedule to be checked to confirm the installation clearance and requirement. 1. Secondary frame packing 2. pipe feeds location
A14: 01 | B14: Architecture | C14: ARC_SOG Floor Insulation | D14: Slab on Grade Insulation | E14: Sometimes, the structural model does not show the insulation and barely identifies any service clashes that could affect the slab buildup
A15: 02 | B15: Structural | C15: STR_Seismic Elements | D15: Seismic Elements
A16: 02 | B16: Structural | C16: STR_Conc work Excl Floor Slab | D16: Structural - Concrete work Excluding Floor Slab
A17: 02 | B17: Structural | C17: STR_Steelwork (Bracing and Columns) | D17: Structural - Steelwork (Bracing and Columns)
A18: 02 | B18: Structural | C18: STR Floor | D18: Structural Floor
A19: 03 | B19: Services - Plumbing and Drainage | C19: HYD_Uninsulated Pipes and Acc | D19: Pipe, Accessories and Fittings - HYD (Including Flexi and UnInsulated)
A20: 03 | B20: Services - Plumbing and Drainage | C20: HYD_Pipe Insulation | D20: Pipe Insulation only
A21: 03 | B21: Services - Plumbing and Drainage | C21: HYD_Uninsulated Hot and Cold Pipes and Acc | D21: Pipe, Accessories and Fittings - HOT AND COLD (Excl Flexi and Insulated)
A22: 03 | B22: Services - Plumbing and Drainage | C22: HYD_Hot and Cold Insulation | D22: Pipe Insulation Only
A23: 03 | B23: Services - Plumbing and Drainage | C23: HYD_Plumbing Fixture | D23: HYD_Plumbing Fixture
A24: 04 | B24: Services - Mechanical | C24: MEC_Air Terminals | D24: Air Terminals
A25: 04 | B25: Services - Mechanical | C25: MEC_Uninsulated Duct and Acc | D25: Uninsulated Duct, accessories and Duct Fittings (Excl Flexi) | E25: Valves
A26: 04 | B26: Services - Mechanical | C26: MEC_Duct Insulation | D26: Duct Insulation
A27: 04 | B27: Services - Mechanical | C27: MEC_Pipe Insulation | D27: Insulated Pipe, Accessories and Fittings
A28: 04 | B28: Services - Mechanical | C28: MEC_Uninsulated Pipes and Acc | D28: Uninsulated Pipe, Accessories and Fittings
A29: 04 | B29: Services - Mechanical | C29: MEC_Uninulated Flexi duct | D29: Flexi Ducts with no insulation
A30: 04 | B30: Services - Mechanical | C30: MEC_Equipment | D30: Mechanical Equipment | E30: Final procurement schedule to be checked to confirm the installation clearance
A31: 05 | B31: Services - Electrical | C31: ELE_Cable Tray and Fittings | D31: Cable Tray, Fittings
A32: 05 | B32: Services - Electrical | C32: ELE_Conduit* | D32: Conduit* | E32: Underground conduit to inground foundation beam
A33: 05 | B33: Services - Electrical | C33: ELE_Electrical Equip. | D33: Electrical Equipment | E33: Final procurement schedule to be checked to confirm the installation clearance
A34: 05 | B34: Services - Electrical | C34: ELE_Small Devices | D34: Fire Device, Comms Devices, Security Devices, Electrical, Lighting Switches, Nurse Devices & Electrical Fixture* | E34: The items are categories as small face based fixtures. Suggest to use Tag to identify who need to assign to.
A35: 05 | B35: Services - Electrical | C35: ELE_Services Lighting Fixtures | D35: Services Lighting Fixtures | E35: The final procurement schedule should be reviewed to verify installation clearances and ensure the allowed product depth.
A36: 06 | B36: Services - Fire | C36: FIR_Fire Pipes | D36: Pipe, Accessories and Fittings - FIRE- (Including Flexi and Insulated)
A37: 06 | B37: Services - Fire | C37: FIR_Sprinklers Heads | D37: Sprinklers Heads
A38: 06 | B38: Services - Fire | C38: FIR_Heat or Smoke Detectors | D38: Fire Heating or Smoke Detectors

Sheet Seismic Restraints Technical
A1: Table 15, NZS4219:2009 | B1: Minimum Clearances (mm)
A2: Condition - Being Considered | B2: Horizontal | C2: Vertical
A3: Unrestained components to unrestained components | B3: 250 | C3: 50
A4: Unrestained components to restained components | B4: 150 | C4: 50
A5: Restained components to restained components | B5: 50 | C5: 50
A6: Penetration through structure (such as walls and floors) | B6: 50 | C6: 50
A7: Note: Ceiling hangers and braces are considered to be restrained components for the purpose of this table
A9: Notes:
A10: Rigid ductwork, where the hanger length from the top of the duct to the structure support exceeds 200mm shall be restrained against seismic forces.
A11: Pipework exceeding 50mm in diameter and located more than 150mm from the structural support shall be laterally braced. The spacing of transverse and longitudinal bracing shall be in accordance with nzs 4219, section 3.6.
A12: Equipment within the ceiling exceeding 10kg mass shall be independently fixed and braced to the structure and separated from the ceiling by 25mm all around to allow for independent movement between equipment and ceiling
A13: Clearance of services at all penetrations through structure or partition walls shall be 12mm for ductwork, 15mm for pipework and 25mm for cable tray. All services shall be restrained at penetrations through structure and partition walls. The design engineer of the structure / partition walls shall ensure the structure / partition walls shall be capable of resisting lateral seismic load imposed on it due to restraint provided at the penetrations
A14: Piping systems (NZS 4219, Section 5.8)
A15: Ducting (Section 5.9)
A16: Suspended equipment (Section 5.13)
A17: Floor-mounted components (Section 3.7)
A18: Physical interference: Ensure that seismic restraints, such as braces or fixings, do not interfere with the routing of pipes or ducts.
A19: Clearance and access: Check that adequate clearances are maintained around seismic restraints and that access for maintenance or inspection remains unimpeded (as per Section 5.15 for plinths and clearances).
A20: Load path conflicts: Ensure the load paths for seismic restraints are clear and do not intersect with other building systems, as per the requirements in Section 2 (General Requirements)

Sheet #7 Notes
A1: Architecture | B1: Flexbile
A2: Structure
A3: Gravity Pipework
A4: Mechanical
A5: Electrical
A6: Fire | B6: More Flexible
